<mujoco model="panda1">
  <compiler angle="radian" meshdir="assets" autolimits="true"/>

  <option integrator="implicitfast"/>

  <default>
    <default class="panda1">

      <material specular="0.5" shininess="0.25"/>

      <joint armature="0.1" damping="1" axis="0 0 1" range="-2.8973 2.8973"/>

      <general dyntype="none" biastype="affine" ctrlrange="-2.8973 2.8973" forcerange="-87 87"/>
      
      <default class="finger1">
        <joint axis="0 1 0" type="slide" range="0 0.04"/>
      </default>

      <default class="visual1">
        <geom type="mesh" contype="0" conaffinity="0" group="2"/>
      </default>
      <default class="collision1">
        <geom type="mesh" group="3"/>
        <default class="fingertip_pad_collision_1_1">
          <geom type="box" size="0.0085 0.004 0.0085" pos="0 0.0055 0.0445"/>
        </default>
        <default class="fingertip_pad_collision_2_1">
          <geom type="box" size="0.003 0.002 0.003" pos="0.0055 0.002 0.05"/>
        </default>
        <default class="fingertip_pad_collision_3_1">
          <geom type="box" size="0.003 0.002 0.003" pos="-0.0055 0.002 0.05"/>
        </default>
        <default class="fingertip_pad_collision_4_1">
          <geom type="box" size="0.003 0.002 0.0035" pos="0.0055 0.002 0.0395"/>
        </default>
        <default class="fingertip_pad_collision_5_1">
          <geom type="box" size="0.003 0.002 0.0035" pos="-0.0055 0.002 0.0395"/>
        </default>
      </default>
    </default>
  </default>

  <asset>
    <material class="panda1" name="white1" rgba="1 1 1 1"/>
    <material class="panda1" name="off_white1" rgba="0.901961 0.921569 0.929412 1"/>
    <material class="panda1" name="black1" rgba="0.25 0.25 0.25 1"/>
    <material class="panda1" name="green1" rgba="0 1 0 1"/>
    <material class="panda1" name="light_blue1" rgba="0.039216 0.541176 0.780392 1"/>

    <!-- Collision meshes -->
    <mesh name="link0_c_1" file="link0.stl"/>
    <mesh name="link1_c_1" file="link1.stl"/>
    <mesh name="link2_c_1" file="link2.stl"/>
    <mesh name="link3_c_1" file="link3.stl"/>
    <mesh name="link4_c_1" file="link4.stl"/>
    <mesh name="link5_c0_1" file="link5_collision_0.obj"/>
    <mesh name="link5_c1_1" file="link5_collision_1.obj"/>
    <mesh name="link5_c2_1" file="link5_collision_2.obj"/>
    <mesh name="link6_c_1" file="link6.stl"/>
    <mesh name="link7_c_1" file="link7.stl"/>
    <mesh name="hand_c_1" file="hand.stl"/>

    <!-- Visual meshes -->
    <mesh name="link0_0_1" file="link0_0.obj"/>
    <mesh name="link0_1_1" file="link0_1.obj"/>
    <mesh name="link0_2_1" file="link0_2.obj"/>
    <mesh name="link0_3_1" file="link0_3.obj"/>
    <mesh name="link0_4_1" file="link0_4.obj"/>
    <mesh name="link0_5_1" file="link0_5.obj"/>
    <mesh name="link0_7_1" file="link0_7.obj"/>
    <mesh name="link0_8_1" file="link0_8.obj"/>
    <mesh name="link0_9_1" file="link0_9.obj"/>
    <mesh name="link0_10_1" file="link0_10.obj"/>
    <mesh name="link0_11_1" file="link0_11.obj"/>
    <mesh name="link1_1" file="link1.obj"/>
    <mesh name="link2_1" file="link2.obj"/>
    <mesh name="link3_0_1" file="link3_0.obj"/>
    <mesh name="link3_1_1" file="link3_1.obj"/>
    <mesh name="link3_2_1" file="link3_2.obj"/>
    <mesh name="link3_3_1" file="link3_3.obj"/>
    <mesh name="link4_0_1" file="link4_0.obj"/>
    <mesh name="link4_1_1" file="link4_1.obj"/>
    <mesh name="link4_2_1" file="link4_2.obj"/>
    <mesh name="link4_3_1" file="link4_3.obj"/>
    <mesh name="link5_0_1" file="link5_0.obj"/>
    <mesh name="link5_1_1" file="link5_1.obj"/>
    <mesh name="link5_2_1" file="link5_2.obj"/>
    <mesh name="link6_0_1" file="link6_0.obj"/>
    <mesh name="link6_1_1" file="link6_1.obj"/>
    <mesh name="link6_2_1" file="link6_2.obj"/>
    <mesh name="link6_3_1" file="link6_3.obj"/>
    <mesh name="link6_4_1" file="link6_4.obj"/>
    <mesh name="link6_5_1" file="link6_5.obj"/>
    <mesh name="link6_6_1" file="link6_6.obj"/>
    <mesh name="link6_7_1" file="link6_7.obj"/>
    <mesh name="link6_8_1" file="link6_8.obj"/>
    <mesh name="link6_9_1" file="link6_9.obj"/>
    <mesh name="link6_10_1" file="link6_10.obj"/>
    <mesh name="link6_11_1" file="link6_11.obj"/>
    <mesh name="link6_12_1" file="link6_12.obj"/>
    <mesh name="link6_13_1" file="link6_13.obj"/>
    <mesh name="link6_14_1" file="link6_14.obj"/>
    <mesh name="link6_15_1" file="link6_15.obj"/>
    <mesh name="link6_16_1" file="link6_16.obj"/>
    <mesh name="link7_0_1" file="link7_0.obj"/>
    <mesh name="link7_1_1" file="link7_1.obj"/>
    <mesh name="link7_2_1" file="link7_2.obj"/>
    <mesh name="link7_3_1" file="link7_3.obj"/>
    <mesh name="link7_4_1" file="link7_4.obj"/>
    <mesh name="link7_5_1" file="link7_5.obj"/>
    <mesh name="link7_6_1" file="link7_6.obj"/>
    <mesh name="link7_7_1" file="link7_7.obj"/>
    <mesh name="hand_0_1" file="hand_0.obj"/>
    <mesh name="hand_1_1" file="hand_1.obj"/>
    <mesh name="hand_2_1" file="hand_2.obj"/>
    <mesh name="hand_3_1" file="hand_3.obj"/>
    <mesh name="hand_4_1" file="hand_4.obj"/>
    <mesh name="finger_0_1" file="finger_0.obj"/>
    <mesh name="finger_1_1" file="finger_1.obj"/>
  </asset>

  <worldbody>
    <light name="top1" pos="0 0 2" mode="trackcom"/>
    <body name="link0_1" childclass="panda1" pos="0.2 -0.4 0"  quat="1 0 0 1">
      <site name="panda_site0_1" pos="0 0 0" size="0.01" rgba="1 0 0 1" type="sphere" />
      <inertial mass="0.629769" pos="-0.041018 -0.00014 0.049974"
        fullinertia="0.00315 0.00388 0.004285 8.2904e-7 0.00015 8.2299e-6"/>
      <geom mesh="link0_0_1" material="off_white1" class="visual1"/>
      <geom mesh="link0_1_1" material="black1" class="visual1"/>
      <geom mesh="link0_2_1" material="off_white1" class="visual1"/>
      <geom mesh="link0_3_1" material="black1" class="visual1"/>
      <geom mesh="link0_4_1" material="off_white1" class="visual1"/>
      <geom mesh="link0_5_1" material="black1" class="visual1"/>
      <geom mesh="link0_7_1" material="white1" class="visual1"/>
      <geom mesh="link0_8_1" material="white1" class="visual1"/>
      <geom mesh="link0_9_1" material="black1" class="visual1"/>
      <geom mesh="link0_10_1" material="off_white1" class="visual1"/>
      <geom mesh="link0_11_1" material="white1" class="visual1"/>
      <geom mesh="link0_c_1" class="collision1"/>
      <body name="link1_1" pos="0 0 0.333">
        <site name="panda_site1_1" pos="0 0 0" size="0.01" rgba="1 0 0 1" type="sphere" />
        <inertial mass="4.970684" pos="0.003875 0.002081 -0.04762"
          fullinertia="0.70337 0.70661 0.0091170 -0.00013900 0.0067720 0.019169"/>
        <joint name="joint1_1"/>
        <geom material="white1" mesh="link1_1" class="visual1"/>
        <geom mesh="link1_c_1" class="collision1"/>
        <body name="link2_1" quat="1 -1 0 0">
        <site name="panda_site2_1" pos="0 0 0" size="0.01" rgba="1 0 0 1" type="sphere" />
          <inertial mass="0.646926" pos="-0.003141 -0.02872 0.003495"
            fullinertia="0.0079620 2.8110e-2 2.5995e-2 -3.925e-3 1.0254e-2 7.04e-4"/>
          <joint name="joint2_1" range="-1.7628 1.7628"/>
          <geom material="white1" mesh="link2_1" class="visual1"/>
          <geom mesh="link2_c_1" class="collision1"/>
          <body name="link3_1" pos="0 -0.316 0" quat="1 1 0 0">
            <site name="panda_site3_1" pos="0 0 0" size="0.01" rgba="1 0 0 1" type="sphere" />
            <joint name="joint3_1"/>
            <inertial mass="3.228604" pos="2.7518e-2 3.9252e-2 -6.6502e-2"
              fullinertia="3.7242e-2 3.6155e-2 1.083e-2 -4.761e-3 -1.1396e-2 -1.2805e-2"/>
            <geom mesh="link3_0_1" material="white1" class="visual1"/>
            <geom mesh="link3_1_1" material="white1" class="visual1"/>
            <geom mesh="link3_2_1" material="white1" class="visual1"/>
            <geom mesh="link3_3_1" material="black1" class="visual1"/>
            <geom mesh="link3_c_1" class="collision1"/>
            <body name="link4_1" pos="0.0825 0 0" quat="1 1 0 0">
              <site name="panda_site4_1" pos="0 0 0" size="0.01" rgba="1 0 0 1" type="sphere" />
              <inertial mass="3.587895" pos="-5.317e-2 1.04419e-1 2.7454e-2"
                fullinertia="2.5853e-2 1.9552e-2 2.8323e-2 7.796e-3 -1.332e-3 8.641e-3"/>
              <joint name="joint4_1" range="-3.0718 -0.0698"/>
              <geom mesh="link4_0_1" material="white1" class="visual1"/>
              <geom mesh="link4_1_1" material="white1" class="visual1"/>
              <geom mesh="link4_2_1" material="black1" class="visual1"/>
              <geom mesh="link4_3_1" material="white1" class="visual1"/>
              <geom mesh="link4_c_1" class="collision1"/>
              <body name="link5_1" pos="-0.0825 0.384 0" quat="1 -1 0 0">
                <site name="panda_site5_1" pos="0 0 0" size="0.01" rgba="1 0 0 1" type="sphere" />
                <inertial mass="1.225946" pos="-1.1953e-2 4.1065e-2 -3.8437e-2"
                  fullinertia="3.5549e-2 2.9474e-2 8.627e-3 -2.117e-3 -4.037e-3 2.29e-4"/>
                <joint name="joint5_1"/>
                <geom mesh="link5_0_1" material="black1" class="visual1"/>
                <geom mesh="link5_1_1" material="white1" class="visual1"/>
                <geom mesh="link5_2_1" material="white1" class="visual1"/>
                <geom mesh="link5_c0_1" class="collision1"/>
                <geom mesh="link5_c1_1" class="collision1"/>
                <geom mesh="link5_c2_1" class="collision1"/>
                <body name="link6_1" quat="1 1 0 0">
                  <site name="panda_site6_1" pos="0 0 0" size="0.01" rgba="1 0 0 1" type="sphere" />
                  <inertial mass="1.666555" pos="6.0149e-2 -1.4117e-2 -1.0517e-2"
                    fullinertia="1.964e-3 4.354e-3 5.433e-3 1.09e-4 -1.158e-3 3.41e-4"/>
                  <joint name="joint6_1" range="-0.0175 3.7525"/>
                  <geom mesh="link6_0_1" material="off_white1" class="visual1"/>
                  <geom mesh="link6_1_1" material="white1" class="visual1"/>
                  <geom mesh="link6_2_1" material="black1" class="visual1"/>
                  <geom mesh="link6_3_1" material="white1" class="visual1"/>
                  <geom mesh="link6_4_1" material="white1" class="visual1"/>
                  <geom mesh="link6_5_1" material="white1" class="visual1"/>
                  <geom mesh="link6_6_1" material="white1" class="visual1"/>
                  <geom mesh="link6_7_1" material="light_blue1" class="visual1"/>
                  <geom mesh="link6_8_1" material="light_blue1" class="visual1"/>
                  <geom mesh="link6_9_1" material="black1" class="visual1"/>
                  <geom mesh="link6_10_1" material="black1" class="visual1"/>
                  <geom mesh="link6_11_1" material="white1" class="visual1"/>
                  <geom mesh="link6_12_1" material="green1" class="visual1"/>
                  <geom mesh="link6_13_1" material="white1" class="visual1"/>
                  <geom mesh="link6_14_1" material="black1" class="visual1"/>
                  <geom mesh="link6_15_1" material="black1" class="visual1"/>
                  <geom mesh="link6_16_1" material="white1" class="visual1"/>
                  <geom mesh="link6_c_1" class="collision1"/>
                  <body name="link7_1" pos="0.088 0 0" quat="1 1 0 0">
                    <site name="panda_site7_1" pos="0 0 0" size="0.01" rgba="1 0 0 1" type="sphere" />
                    <inertial mass="7.35522e-01" pos="1.0517e-2 -4.252e-3 6.1597e-2"
                      fullinertia="1.2516e-2 1.0027e-2 4.815e-3 -4.28e-4 -1.196e-3 -7.41e-4"/>
                    <joint name="joint7_1"/>
                    <geom mesh="link7_0_1" material="white1" class="visual1"/>
                    <geom mesh="link7_1_1" material="black1" class="visual1"/>
                    <geom mesh="link7_2_1" material="black1" class="visual1"/>
                    <geom mesh="link7_3_1" material="black1" class="visual1"/>
                    <geom mesh="link7_4_1" material="black1" class="visual1"/>
                    <geom mesh="link7_5_1" material="black1" class="visual1"/>
                    <geom mesh="link7_6_1" material="black1" class="visual1"/>
                    <geom mesh="link7_7_1" material="white1" class="visual1"/>
                    <geom mesh="link7_c_1" class="collision1"/>
                    <body name="hand1" pos="0 0 0.107" quat="0.9238795 0 0 -0.3826834">
                      <site name="panda_site8_1" pos="0 0 -0.1" size="0.01" rgba="1 0 0 1" type="sphere" />
                      <inertial mass="0.73" pos="-0.01 0 0.03" diaginertia="0.001 0.0025 0.0017"/>
                      <geom mesh="hand_0_1" material="off_white1" class="visual1"/>
                      <geom mesh="hand_1_1" material="black1" class="visual1"/>
                      <geom mesh="hand_2_1" material="black1" class="visual1"/>
                      <geom mesh="hand_3_1" material="white1" class="visual1"/>
                      <geom mesh="hand_4_1" material="off_white1" class="visual1"/>
                      <geom mesh="hand_c_1" class="collision1"/>
                      <body name="left_finger1" pos="0 0 0.0584">
                        <inertial mass="0.015" pos="0 0 0" diaginertia="2.375e-6 2.375e-6 7.5e-7"/>
                        <joint name="finger_joint1_1" class="finger1"/>
                        <geom mesh="finger_0_1" material="off_white1" class="visual1"/>
                        <geom mesh="finger_1_1" material="black1" class="visual1"/>
                        <geom mesh="finger_0_1" class="collision1"/>
                        <geom class="fingertip_pad_collision_1_1"/>
                        <geom class="fingertip_pad_collision_2_1"/>
                        <geom class="fingertip_pad_collision_3_1"/>
                        <geom class="fingertip_pad_collision_4_1"/>
                        <geom class="fingertip_pad_collision_5_1"/>
                      </body>
                      <body name="right_finger1" pos="0 0 0.0584" quat="0 0 0 1">
                        <inertial mass="0.015" pos="0 0 0" diaginertia="2.375e-6 2.375e-6 7.5e-7"/>
                        <joint name="finger_joint2_1" class="finger1"/>
                        <geom mesh="finger_0_1" material="off_white1" class="visual1"/>
                        <geom mesh="finger_1_1" material="black1" class="visual1"/>
                        <geom mesh="finger_0_1" class="collision1"/>
                        <geom class="fingertip_pad_collision_1_1"/>
                        <geom class="fingertip_pad_collision_2_1"/>
                        <geom class="fingertip_pad_collision_3_1"/>
                        <geom class="fingertip_pad_collision_4_1"/>
                        <geom class="fingertip_pad_collision_5_1"/>
                      </body>
                    </body>
                  </body>
                </body>
              </body>
            </body>
          </body>
        </body>
      </body>
    </body>
  </worldbody>

  <tendon>
    <fixed name="split1">
      <joint joint="finger_joint1_1" coef="0.5"/>
      <joint joint="finger_joint2_1" coef="0.5"/>
    </fixed>
  </tendon>

  <equality>
    <joint joint1="finger_joint1_1" joint2="finger_joint2_1" solimp="0.95 0.99 0.001" solref="0.005 1"/>
  </equality>

  <actuator>
    <general class="panda1" name="actuator1_1" joint="joint1_1" gainprm="4500" biasprm="0 -4500 -450"/>
    <general class="panda1" name="actuator2_1" joint="joint2_1" gainprm="4500" biasprm="0 -4500 -450"
      ctrlrange="-1.7628 1.7628"/>
    <general class="panda1" name="actuator3_1" joint="joint3_1" gainprm="3500" biasprm="0 -3500 -350"/>
    <general class="panda1" name="actuator4_1" joint="joint4_1" gainprm="3500" biasprm="0 -3500 -350"
      ctrlrange="-3.0718 -0.0698"/>
    <general class="panda1" name="actuator5_1" joint="joint5_1" gainprm="2000" biasprm="0 -2000 -200" forcerange="-12 12"/>
    <general class="panda1" name="actuator6_1" joint="joint6_1" gainprm="2000" biasprm="0 -2000 -200" forcerange="-12 12"
      ctrlrange="-0.0175 3.7525"/>
    <general class="panda1" name="actuator7_1" joint="joint7_1" gainprm="2000" biasprm="0 -2000 -200" forcerange="-12 12"/>
    <!-- Remap original ctrlrange (0, 0.04) to (0, 255): 0.04 * 100 / 255 = 0.01568627451 -->
    <general class="panda1" name="actuator8_1" tendon="split1" forcerange="-100 100" ctrlrange="0 255"
      gainprm="0.01568627451 0 0" biasprm="0 -100 -10"/>
  </actuator>

</mujoco>
